# 异常处理方式和日志打印方式

```java

		logger.debug("------测试1, 测试logger.error函数的使用方法和输出信息");
		try {
			throwException();
		} catch (Exception e) {
			// 用debug方法, 否则debug和error不是同一个缓冲器, 输出字符的顺序会乱
			logger.debug("捕获到异常", e);
		}
		
		// 这个先不测, 因为printStackTrace会打印到error上, 因为debug和error不用同一个缓冲区, 字符顺序会颠倒
//		logger.debug("------测试2, 测试e.printStackTrace函数的输出信息");
//		try {
//			throwException();
//		} catch (Exception e) {
//			e.printStackTrace();
//		}
		
		logger.debug("------测试3, 测试catch语句中又出现异常, 使得原异常无法向上抛出. 解决方法: 对此函数再嵌一层try catch");
		try {
			try {
				throwException();
			} catch (Exception e) {
				// 另一条异常信息, 它使得原本想向上抛出的throw new Exception(e)失效!!!!
				// 解决方法: 对此函数再嵌一层try catch
				throwException();
				throw new Exception("捕获到异常并向上抛出, 而这条语句缺没得到执行机会, 这条异常会丢失!!!!", e);
			}
		} catch (Exception e) {
			logger.debug(e);
		}
		
		logger.debug("------测试4, catch中原样抛出throw new Exception时, 打印堆栈是否太乱?");
		logger.debug("修改方法: 如果对异常进行了处理, 则应输出异常调用堆栈; 如果没处理, 而是向外抛出了异常, 则不应打印调用堆栈, 而仅仅打印一行提示信息即可, 否则外面处理异常的方法会打印调用堆栈, 会让调用堆栈重复打印, 影响日志");
		try {
			try {
				throwException();
			} catch (Exception e) {
				logger.debug("------开始打印日志, 在中间catch块中");
				logger.debug(e);
				logger.debug("------结束打印日志, 在中间catch块中");
				throw new Exception(e);
			}
		} catch (Exception e) {
			logger.debug(e);
		}
		
		logger.debug("------测试5, logger.debug的重载方法的区别");
		try {
			throwException();
		} catch (Exception e) {
			// 一个参数时, 打印一句话
			logger.debug(e);
			logger.debug("\n");
			// 两个参数时, 第一个参数作为一句话打印, 第二个参数会打印调用堆栈
			logger.debug("处理异常", e);
		}
		
		/**
		 * 总结:
		 * logger.debug(str) 打印字符
		 * logger.debug(str, e) 打印字符和异常堆栈
		 * catch中若未处理异常, 直接将异常抛给外面, 则不应打印异常堆栈!!! 否则异常堆栈重复打印, 影响日志查看
		 * catch中若又出现新异常, 要嵌套try catch, 否则原异常得不到throw的机会!!!
		 */
		 
```









```java
static public int test1() throws Exception {
	try {
		throw new Exception("");
	} catch (Exception e) {
		throw new Exception("");
	} finally {
		// 屏蔽了catch中的异常!!!
		return 1;
	}
}

// 总结: finally中的return语句, 会使catch中的异常无效!
// 因此不能再finally中用return!!!

static public int test2() throws Exception {
	int i = 0;
	try {
		if (true)
			throw new Exception("");
		return i; // 位置1
	} catch (Exception e) {
		return i; // 位置2
	} finally {
		++i; // 位置3
	}
//	return i; // 位置4
	
	// 总结: 位置1到4的return分别是在try中, catch中, finally中, 外部.
	// 其中finally中和外部的return一定会执行到, 因此其中一个只要存在, 函数即可返回, 编译就正常
	// 而try中的return, 会因出现异常而无法执行; catch中的return会因未出现异常而无法执行. 因此两者必须同时存在

	// 总结: 方便起见, return应放在外部
	
	// 以上例子最终会返回0, 原因是catch在执行return i时, 将i暂存起来(此时i是0), 再执行finally(i递增1变成1);
	// finally执行完成回到catch中, 再取出i(还是刚才的0), 返回0.
	
}

public static void main(String[] args) throws Exception {
	System.out.println(DcGrantRetamtModelAction.test1());
	System.out.println(DcGrantRetamtModelAction.test2());
}
```